<?xml version="1.0"?>
<robot xmlns:xacro="http://ros.org/wiki/xacro" name="prius">
  <link name="chassis">
    <visual>
      <origin xyz="0 0 0" rpy="0 0 0"/>
      <geometry>
        <mesh filename="package://prius_description/meshes/Hybrid.obj" scale="0.01 0.01 0.01"/>
      </geometry>
    </visual>

    <collision name="chassis">
      <origin xyz="0.0 0.05 0.625" rpy="0 0 0"/>
      <geometry>
        <box size="1.7526 2.1 0.95"/>
      </geometry>
    </collision>

    <collision name="front_bumper">
      <origin xyz="0.0 -2.0 0.458488" rpy="0.0 0 0"/>
      <geometry>
        <box size="1.337282 0.48 0.566691"/>
      </geometry>
    </collision>

    <collision name="hood">
      <origin xyz="0.0 -1.900842 0.676305" rpy="0.341247 0 0"/>
      <geometry>
        <box size="1.597968 0.493107 0.265468"/>
      </geometry>
    </collision>

    <collision name="windshield">
      <origin xyz="0.0 -0.875105 1.032268" rpy="0.335476 0 0"/>
      <geometry>
        <box size="1.168381 1.654253 0.272347"/>
      </geometry>
    </collision>

    <collision name="top_front">
      <origin xyz="0.0 0.161236 1.386042" rpy="0.135030 0 0"/>
      <geometry>
        <box size="1.279154 0.625988 0.171868"/>
      </geometry>
    </collision>

    <collision name="top_rear">
      <origin xyz="0.0 0.817696 1.360069" rpy="-0.068997 0 0"/>
      <geometry>
        <box size="1.285130 0.771189 0.226557"/>
      </geometry>
    </collision>

    <collision name="rear_window">
      <origin xyz="0.0 1.640531 1.175126" rpy="-0.262017 0 0"/>
      <geometry>
        <box size="1.267845 1.116344 0.244286"/>
      </geometry>
    </collision>

    <collision name="trunk">
      <origin xyz="0.0 1.637059 0.888180" rpy="0.0 0 0"/>
      <geometry>
        <box size="1.788064 1.138988 0.482746"/>
      </geometry>
    </collision>

    <collision name="back_bumper">
      <origin xyz="0.0 2.054454 0.577870" rpy="0.0 0 0"/>
      <geometry>
        <box size="1.781650 0.512093 0.581427"/>
      </geometry>
    </collision>

    <inertial>
      <mass value="1356.0"/>
      <origin xyz="0 0 0.48"/>
      <inertia ixx="2581.13354740" ixy="0.0" ixz="0.0" iyy="591.30846112" iyz="0.0" izz="2681.95008628"/>
    </inertial>
  </link>
  <link name="fl_axle">
    <inertial>
      <mass value="1"/>
      <origin xyz="0 0 0"/>
      <inertia ixx="0.001" ixy="0.0" ixz="0.0" iyy="0.001" iyz="0.0" izz="0.001"/>
    </inertial>
  </link>
  <link name="fr_axle">
    <inertial>
      <mass value="1"/>
      <origin xyz="0 0 0"/>
      <inertia ixx="0.001" ixy="0.0" ixz="0.0" iyy="0.001" iyz="0.0" izz="0.001"/>
    </inertial>
  </link>
  <link name="front_left_wheel">
    <inertial>
      <mass value="11"/>
      <origin xyz="0 0 0"/>
      <inertia ixx="0.58631238" ixy="0.0" ixz="0.0" iyy="0.33552910" iyz="0.0" izz="0.33552910"/>
    </inertial>
    <collision name="collision">
      <geometry>
        <sphere radius="0.31265"/>
      </geometry>
    </collision>
  </link>
  <link name="front_right_wheel">
    <inertial>
      <mass value="11"/>
      <origin xyz="0 0 0"/>
      <inertia ixx="0.58631238" ixy="0.0" ixz="0.0" iyy="0.33552910" iyz="0.0" izz="0.33552910"/>
    </inertial>
    <collision name="collision">
      <geometry>
        <sphere radius="0.31265"/>
      </geometry>
    </collision>
  </link>
  <link name="rear_left_wheel">
    <inertial>
      <mass value="11"/>
      <origin xyz="0 0 0"/>
      <inertia ixx="0.58631238" ixy="0.0" ixz="0.0" iyy="0.33552910" iyz="0.0" izz="0.33552910"/>
    </inertial>
    <collision name="collision">
      <geometry>
        <sphere radius="0.31265"/>
      </geometry>
    </collision>
  </link>
  <link name="rear_right_wheel">
    <inertial>
      <mass value="11"/>
      <origin xyz="0 0 0"/>
      <inertia ixx="0.58631238" ixy="0.0" ixz="0.0" iyy="0.33552910" iyz="0.0" izz="0.33552910"/>
    </inertial>
    <collision name="collision">
      <geometry>
        <sphere radius="0.31265"/>
      </geometry>
    </collision>
  </link>
  <joint name="fl_steer_joint" type="continuous">
    <parent link="chassis"/>
    <child link="fl_axle"/>
    <origin xyz="0.767 -1.41 0.3" rpy="-0.089 0 0"/>
    <axis xyz="0 0 1"/>
  </joint>
  <joint name="fr_steer_joint" type="continuous">
    <parent link="chassis"/>
    <child link="fr_axle"/>
    <origin xyz="-0.767 -1.41 0.3" rpy="-0.089 0 0"/>
    <axis xyz="0 0 1"/>
  </joint>
  <joint name="front_left_wheel_joint" type="continuous">
    <parent link="fl_axle"/>
    <child link="front_left_wheel"/>
    <origin xyz="0 0 0" rpy="0 0 0"/>
    <axis xyz="1 0 0"/>
  </joint>
  <joint name="front_right_wheel_joint" type="continuous">
    <parent link="fr_axle"/>
    <child link="front_right_wheel"/>
    <origin xyz="0 0 0" rpy="0 0 0"/>
    <axis xyz="1 0 0"/>
  </joint>
  <joint name="rear_left_wheel_joint" type="continuous">
    <parent link="chassis"/>
    <child link="rear_left_wheel"/>
    <origin xyz="0.793 1.45 0.3" rpy="0 0 0"/>
    <axis xyz="1 0 0"/>
  </joint>
  <joint name="rear_right_wheel_joint" type="continuous">
    <parent link="chassis"/>
    <child link="rear_right_wheel"/>
    <origin xyz="-0.793 1.45 0.3" rpy="0 0 0"/>
    <axis xyz="1 0 0"/>
  </joint>
  <gazebo>
      <plugin name="pruis_hybrid_drive" filename="libPriusHybridPlugin.so">
        <!-- ... plugin parameters ... -->
    </plugin>
  </gazebo>
</robot>
